function UserError(message) {
    this.message = message || '默认信息';
    this.name = 'UserError';
}

UserError.prototype = new Error();
UserError.prototype.constructor = UserError;


try {
    throw new UserError('出错了！');
} catch (e) {
    if (e instanceof EvalError) {
        console.log(e.name + ": " + e.message);
    } else if (e instanceof RangeError) {
        console.log(e.name + ": " + e.message);
    }
} finally {
    console.log('FINALLY');
}

function f() {
    try {
        console.log(0);
        throw 'bug';
    } catch (e) {
        console.log(1);
        return true; // 这句原本会延迟到 finally 代码块结束再执行
        console.log(2); // 不会运行
    } finally {
        console.log(3);
        return false; // 这句会覆盖掉前面那句 return
        console.log(4); // 不会运行
    }

    console.log(5); // 不会运行
}

var result = f();
// 0
// 1
// 3

result
// false
